 ERROR (SyncWorker_23) [DenonAVR] No connection to /goform/AppCommand.xml end point on host 192.168.1.80
2018-11-27 18:48:14 ERROR (SyncWorker_23) [DenonAVR] Getting renamed and deleted sources failed.
2018-11-27 18:48:15 ERROR (SyncWorker_23) [DenonAVR] Receiver sources list empty. Please check if device is powered on.
2018-11-27 18:48:17 WARNING (SyncWorker_27) [homeassistant.components.media_player.sonos] Loading Sonos via platform config is deprecated.
2018-11-27 18:48:19 WARNING (MainThread) [homeassistant.components.media_player] Setup of platform denonavr is taking over 10 seconds.
2018-11-27 18:48:21 ERROR (MainThread) [homeassistant.components.media_player] Error while setting up platform sonos
Traceback (most recent call last):
 ERROR (SyncWorker_23) [DenonAVR] No connection to /goform/AppCommand.xml end point on host2018-11-27 18:48:07 WARNING (MainThread) [homeassistant.components.http] legacy_api_password support has been enabled. If you don't require it, remove the 'api_password' from your http config.
2018-11-27 18:48:14 ERROR (SyncWorker_23) [DenonAVR] No connection to /goform/AppCommand.xml end point on host 192.168.1.80
2018-11-27 18:48:14 ERROR (SyncWorker_23) [DenonAVR] Getting renamed and deleted sources failed.
2018-11-27 18:48:15 ERROR (SyncWorker_23) [DenonAVR] Receiver sources list empty. Please check if device is powered on.
2018-11-27 18:48:17 WARNING (SyncWorker_27) [homeassistant.components.media_player.sonos] Loading Sonos via platform config is deprecated.
2018-11-27 18:48:19 WARNING (MainThread) [homeassistant.components.media_player] Setup of platform denonavr is taking over 10 seconds.
2018-11-27 18:48:21 ERROR (MainThread) [homeassistant.components.media_player] Error while setting up platform sonos
Traceback (most recent call last):
  File "/srv/homeassistant/lib/python3.6/site-packages/urllib3/connection.py", line 141, in _new_conn
    (self.host, self.port), self.timeout, **extra_kw)
  File "/srv/homeassistant/lib/python3.6/site-packages/urllib3/util/connection.py", line 83, in create_connection
    raise err
  File "/srv/homeassistant/lib/python3.6/site-packages/urllib3/util/connection.py", line 73, in create_connection
    sock.connect(sa)
OSError: [Errno 113] No route to host

During handling of the above exception, another exception occurred:

Traceback (most recent call last):
  File "/srv/homeassistant/lib/python3.6/site-packages/urllib3/connectionpool.py", line 601, in urlopen
    chunked=chunked)
  File "/srv/homeassistant/lib/python3.6/site-packages/urllib3/connectionpool.py", line 357, in _make_request
    conn.request(method, url, **httplib_request_kw)
  File "/usr/local/lib/python3.6/http/client.py", line 1239, in request
    self._send_request(method, url, body, headers, encode_chunked)
  File "/usr/local/lib/python3.6/http/client.py", line 1285, in _send_request
    self.endheaders(body, encode_chunked=encode_chunked)
  File "/usr/local/lib/python3.6/http/client.py", line 1234, in endheaders
    self._send_output(message_body, encode_chunked=encode_chunked)
  File "/usr/local/lib/python3.6/http/client.py", line 1026, in _send_output
    self.send(msg)
  File "/usr/local/lib/python3.6/http/client.py", line 964, in send
    self.connect()
  File "/srv/homeassistant/lib/python3.6/site-packages/urllib3/connection.py", line 166, in connect
    conn = self._new_conn()
  File "/srv/homeassistant/lib/python3.6/site-packages/urllib3/connection.py", line 150, in _new_conn
    self, "Failed to establish a new connection: %s" % e)
urllib3.exceptions.NewConnectionError: <urllib3.connection.HTTPConnection object at 0x7ff3905ed748>: Failed to establish a new connection: [Errno 113] No route to host

During handling of the above exception, another exception occurred:

Traceback (most recent call last):
  File "/srv/homeassistant/lib/python3.6/site-packages/requests/adapters.py", line 449, in send
    timeout=timeout
  File "/srv/homeassistant/lib/python3.6/site-packages/urllib3/connectionpool.py", line 639, in urlopen
    _stacktrace=sys.exc_info()[2])
  File "/srv/homeassistant/lib/python3.6/site-packages/urllib3/util/retry.py", line 388, in increment
    raise MaxRetryError(_pool, url, error or ResponseError(cause))
urllib3.exceptions.MaxRetryError: HTTPConnectionPool(host='192.168.1.90', port=1400): Max retries exceeded with url: /xml/ZoneGroupTopology1.xml (Caused by NewConnectionError('<urllib3.connection.HTTPConnection object at 0x7ff3905ed748>: Failed to establish a new connection: [Errno 113] No route to host',))

During handling of the above exception, another exception occurred:

Traceback (most recent call last):
  File "/srv/homeassistant/lib/python3.6/site-packages/homeassistant/helpers/entity_platform.py", line 128, in _async_setup_platform
    SLOW_SETUP_MAX_WAIT, loop=hass.loop)
  File "/usr/local/lib/python3.6/asyncio/tasks.py", line 358, in wait_for
    return fut.result()
  File "/usr/local/lib/python3.6/concurrent/futures/thread.py", line 56, in run
    result = self.fn(*self.args, **self.kwargs)
  File "/srv/homeassistant/lib/python3.6/site-packages/homeassistant/components/media_player/sonos.py", line 127, in setup_platform
    _setup_platform(hass, config, add_entities, discovery_info)
  File "/srv/homeassistant/lib/python3.6/site-packages/homeassistant/components/media_player/sonos.py", line 185, in _setup_platform
    hass.data[DATA_SONOS].uids.update(p.uid for p in players)
  File "/srv/homeassistant/lib/python3.6/site-packages/homeassistant/components/media_player/sonos.py", line 185, in <genexpr>
    hass.data[DATA_SONOS].uids.update(p.uid for p in players)
  File "/srv/homeassistant/lib/python3.6/site-packages/pysonos/core.py", line 314, in uid
    self._parse_zone_group_state()
  File "/srv/homeassistant/lib/python3.6/site-packages/pysonos/core.py", line 971, in _parse_zone_group_state
    cache_timeout=5)['ZoneGroupState']
  File "/srv/homeassistant/lib/python3.6/site-packages/pysonos/services.py", line 786, in GetZoneGroupState
    return self.send_command('GetZoneGroupState', *args, **kwargs)
  File "/srv/homeassistant/lib/python3.6/site-packages/pysonos/services.py", line 462, in send_command
    args = self.compose_args(action, kwargs)
  File "/srv/homeassistant/lib/python3.6/site-packages/pysonos/services.py", line 337, in compose_args
    for action in self.actions:
  File "/srv/homeassistant/lib/python3.6/site-packages/pysonos/services.py", line 645, in actions
    self._actions = list(self.iter_actions())
  File "/srv/homeassistant/lib/python3.6/site-packages/pysonos/services.py", line 672, in iter_actions
    scpd_body = requests.get(self.base_url + self.scpd_url).content
  File "/srv/homeassistant/lib/python3.6/site-packages/requests/api.py", line 75, in get
    return request('get', url, params=params, **kwargs)
  File "/srv/homeassistant/lib/python3.6/site-packages/requests/api.py", line 60, in request
    return session.request(method=method, url=url, **kwargs)
  File "/srv/homeassistant/lib/python3.6/site-packages/requests/sessions.py", line 524, in request
    resp = self.send(prep, **send_kwargs)
  File "/srv/homeassistant/lib/python3.6/site-packages/requests/sessions.py", line 637, in send
    r = adapter.send(request, **kwargs)
  File "/srv/homeassistant/lib/python3.6/site-packages/requests/adapters.py", line 516, in send
    raise ConnectionError(e, request=request)
requests.exceptions.ConnectionError: HTTPConnectionPool(host='192.168.1.90', port=1400): Max retries exceeded with url: /xml/ZoneGroupTopology1.xml (Caused by NewConnectionError('<urllib3.connection.HTTPConnection object at 0x7ff3905ed748>: Failed to establish a new connection: [Errno 113] No route to host',))
